{   "registryname": "daxingjiayafanyingshi", 
    "localizedname": "大型化学反应室", 
    "requires-blueprint": false, 
    "color": "F8F8FF",
    "parts": [
        {
            "x": 3,
            "y": 3,
            "z": 2,
            "elements": [
                "appliedenergistics2:quartz_glass@0"
            ]
        },
        {
            "x": 2,
            "y": 2,
            "z": 6,
            "elements": [
                "appliedenergistics2:quartz_glass@0"
            ]
        },
        {
            "x": -1,
            "y": 2,
            "z": 0,
            "elements": [
                "appliedenergistics2:quartz_glass@0"
            ]
        },
        {
            "x": -3,
            "y": 0,
            "z": 5,

            "elements": [
                "modularmachinery:blockfluidoutputhatch"
            ]
        },
        {
            "x": -2,
            "y": 4,
            "z": 0,

            "elements": [
                "modularmachinery:blockcasing@4"
            ]
        },
        {
            "x": -1,
            "y": 1,
            "z": 0,
            "elements": [
                "appliedenergistics2:quartz_glass@0"
            ]
        },
        {
            "x": -3,
            "y": 2,
            "z": 5,
            "elements": [
                "appliedenergistics2:quartz_glass@0"
            ]
        },
        {
            "x": 0,
            "y": -1,
            "z": 0,
            "elements": [
                "chisel:cobblestone2@8"
            ]
        },
        {
            "x": 2,
            "y": 3,
            "z": 6,
            "elements": [
                "appliedenergistics2:quartz_glass@0"
            ]
        },
        {
            "x": 3,
            "y": 2,
            "z": 2,
            "elements": [
                "appliedenergistics2:quartz_glass@0"
            ]
        },
        {
            "x": 1,
            "y": 4,
            "z": 4,
            "elements": [
                "appliedenergistics2:quartz_glass@0"
            ]
        },
        {
            "x": 0,
            "y": 4,
            "z": 2,
            "elements": [
                "appliedenergistics2:quartz_glass@0"
            ]
        },
        {
            "x": -2,
            "y": 3,
            "z": 0,
            "elements": [
                "appliedenergistics2:quartz_glass@0"
            ]
        },
        {
            "x": -3,
            "y": -1,
            "z": 5,
            "elements": [
                "chisel:cobblestone2@8"
            ]
        },
        {
            "x": -3,
            "y": 1,
            "z": 5,
            "elements": [
                "appliedenergistics2:quartz_glass@0"
            ]
        },
        {
            "x": 1,
            "y": 0,
            "z": 0,
            "elements": [
                "appliedenergistics2:quartz_glass@0"
            ]
        },
        {
            "x": -2,
            "y": 2,
            "z": 0,
            "elements": [
                "appliedenergistics2:quartz_glass@0"
            ]
        },
        {
            "x": 3,
            "y": 1,
            "z": 2,
            "elements": [
                "appliedenergistics2:quartz_glass@0"
            ]
        },
        {
            "x": -1,
            "y": 4,
            "z": 0,

            "elements": [
                "modularmachinery:blockcasing@4"
            ]
        },
        {
            "x": -2,
            "y": 0,
            "z": 5,
            "elements": [
                "extrautils2:pipe_3@15"
            ]
        },
        {
            "x": 3,
            "y": -1,
            "z": 4,
            "elements": [
                "chisel:cobblestone2@8"
            ]
        },
        {
            "x": 2,
            "y": 4,
            "z": 1,
            "elements": [
                "appliedenergistics2:quartz_glass@0"
            ]
        },
        {
            "x": -2,
            "y": 1,
            "z": 0,
            "elements": [
                "appliedenergistics2:quartz_glass@0"
            ]
        },
        {
            "x": 1,
            "y": -1,
            "z": 0,
            "elements": [
                "chisel:cobblestone2@8"
            ]
        },
        {
            "x": 1,
            "y": 4,
            "z": 2,
            "elements": [
                "appliedenergistics2:quartz_glass@0"
            ]
        },
        {
            "x": -1,
            "y": 3,
            "z": 0,
            "elements": [
                "appliedenergistics2:quartz_glass@0"
            ]
        },
        {
            "x": 3,
            "y": 0,
            "z": 2,

            "elements": [
                "modularmachinery:blockfluidinputhatch"
            ]
        },
        {
            "x": 2,
            "y": 0,
            "z": 0,

            "elements": [
                "modularmachinery:blockenergyinputhatch"
            ]
        },
        {
            "x": 3,
            "y": 1,
            "z": 3,
            "elements": [
                "appliedenergistics2:quartz_glass@0"
            ]
        },
        {
            "x": 1,
            "y": -1,
            "z": 3,
            "elements": [
                "minecraft:obsidian@0"
            ]
        },
        {
            "x": 1,
            "y": 2,
            "z": 0,
            "elements": [
                "appliedenergistics2:quartz_glass@0"
            ]
        },
        {
            "x": 3,
            "y": 3,
            "z": 4,
            "elements": [
                "appliedenergistics2:quartz_glass@0"
            ]
        },
        {
            "x": -1,
            "y": 4,
            "z": 6,

            "elements": [
                "modularmachinery:blockcasing@4"
            ]
        },
        {
            "x": 0,
            "y": 1,
            "z": 2,
            "elements": [
                "minecraft:obsidian@0"
            ]
        },
        {
            "x": 3,
            "y": 4,
            "z": 4,

            "elements": [
                "modularmachinery:blockcasing@4"
            ]
        },
        {
            "x": -3,
            "y": 3,
            "z": 2,
            "elements": [
                "appliedenergistics2:quartz_glass@0"
            ]
        },
        {
            "x": 1,
            "y": 0,
            "z": 6,
            "elements": [
                "appliedenergistics2:quartz_glass@0"
            ]
        },
        {
            "x": 2,
            "y": -1,
            "z": 2,
            "elements": [
                "chisel:cobblestone2@8"
            ]
        },
        {
            "x": -1,
            "y": 4,
            "z": 3,
            "elements": [
                "appliedenergistics2:quartz_glass@0"
            ]
        },
        {
            "x": 1,
            "y": 1,
            "z": 0,
            "elements": [
                "appliedenergistics2:quartz_glass@0"
            ]
        },
        {
            "x": -2,
            "y": -1,
            "z": 0,
            "elements": [
                "chisel:cobblestone2@8"
            ]
        },
        {
            "x": -1,
            "y": -1,
            "z": 5,
            "elements": [
                "chisel:cobblestone2@8"
            ]
        },
        {
            "x": 2,
            "y": 0,
            "z": 3,
            "elements": [
                "extrautils2:pipe_3@15"
            ]
        },
        {
            "x": 1,
            "y": -1,
            "z": 6,
            "elements": [
                "chisel:cobblestone2@8"
            ]
        },
        {
            "x": 1,
            "y": 1,
            "z": 6,
            "elements": [
                "appliedenergistics2:quartz_glass@0"
            ]
        },
        {
            "x": 0,
            "y": 0,
            "z": 2,
            "elements": [
                "minecraft:obsidian@0"
            ]
        },
        {
            "x": -3,
            "y": 2,
            "z": 2,
            "elements": [
                "appliedenergistics2:quartz_glass@0"
            ]
        },
        {
            "x": -1,
            "y": 0,
            "z": 0,
            "elements": [
                "appliedenergistics2:quartz_glass@0"
            ]
        },
        {
            "x": -3,
            "y": 0,
            "z": 2,
            "elements": [
                "appliedenergistics2:quartz_glass@0"
            ]
        },
        {
            "x": 2,
            "y": -1,
            "z": 3,
            "elements": [
                "chisel:cobblestone2@8"
            ]
        },
        {
            "x": 0,
            "y": 0,
            "z": 5,
            "elements": [
                "extrautils2:pipe_3@15"
            ]
        },
        {
            "x": 0,
            "y": 4,
            "z": 3,
            "elements": [
                "appliedenergistics2:quartz_glass@0"
            ]
        },
        {
            "x": -1,
            "y": 2,
            "z": 6,
            "elements": [
                "appliedenergistics2:quartz_glass@0"
            ]
        },
        {
            "x": 2,
            "y": 0,
            "z": 6,
            "elements": [
                "appliedenergistics2:quartz_glass@0"
            ]
        },
        {
            "x": -3,
            "y": 1,
            "z": 2,
            "elements": [
                "appliedenergistics2:quartz_glass@0"
            ]
        },
        {
            "x": 1,
            "y": 4,
            "z": 0,

            "elements": [
                "modularmachinery:blockcasing@4"
            ]
        },
        {
            "x": -3,
            "y": 4,
            "z": 5,

            "elements": [
                "modularmachinery:blockcasing@4"
            ]
        },
        {
            "x": 3,
            "y": 0,
            "z": 3,
            "elements": [
                "appliedenergistics2:quartz_glass@0"
            ]
        },
        {
            "x": -1,
            "y": 3,
            "z": 6,
            "elements": [
                "appliedenergistics2:quartz_glass@0"
            ]
        },
        {
            "x": 1,
            "y": 3,
            "z": 0,
            "elements": [
                "appliedenergistics2:quartz_glass@0"
            ]
        },
        {
            "x": 0,
            "y": -1,
            "z": 6,
            "elements": [
                "chisel:cobblestone2@8"
            ]
        },
        {
            "x": 0,
            "y": 2,
            "z": 2,
            "elements": [
                "extrautils2:pipe_3@15"
            ]
        },
        {
            "x": -3,
            "y": 3,
            "z": 5,
            "elements": [
                "appliedenergistics2:quartz_glass@0"
            ]
        },
        {
            "x": 2,
            "y": 1,
            "z": 6,
            "elements": [
                "appliedenergistics2:quartz_glass@0"
            ]
        },
        {
            "x": -2,
            "y": 0,
            "z": 2,
            "elements": [
                "extrautils2:pipe_3@15"
            ]
        },
        {
            "x": 1,
            "y": 4,
            "z": 6,

            "elements": [
                "modularmachinery:blockcasing@4"
            ]
        },
        {
            "x": 0,
            "y": 4,
            "z": 5,
            "elements": [
                "appliedenergistics2:quartz_glass@0"
            ]
        },
        {
            "x": 2,
            "y": -1,
            "z": 4,
            "elements": [
                "chisel:cobblestone2@8"
            ]
        },
        {
            "x": 2,
            "y": 4,
            "z": 0,

            "elements": [
                "modularmachinery:blockcasing@4"
            ]
        },
        {
            "x": -3,
            "y": 3,
            "z": 4,
            "elements": [
                "appliedenergistics2:quartz_glass@0"
            ]
        },
        {
            "x": 3,
            "y": -1,
            "z": 0,

            "elements": [
                "modularmachinery:blockcasing@4"
            ]
        },
        {
            "x": 0,
            "y": 1,
            "z": 4,
            "elements": [
                "minecraft:obsidian@0"
            ]
        },
        {
            "x": -3,
            "y": 4,
            "z": 4,

            "elements": [
                "modularmachinery:blockcasing@4"
            ]
        },
        {
            "x": 0,
            "y": -1,
            "z": 2,
            "elements": [
                "minecraft:obsidian@0"
            ]
        },
        {
            "x": -1,
            "y": -1,
            "z": 4,
            "elements": [
                "chisel:cobblestone2@8"
            ]
        },
        {
            "x": 2,
            "y": 3,
            "z": 0,
            "elements": [
                "appliedenergistics2:quartz_glass@0"
            ]
        },
        {
            "x": 1,
            "y": -1,
            "z": 5,
            "elements": [
                "chisel:cobblestone2@8"
            ]
        },
        {
            "x": 3,
            "y": -1,
            "z": 6,

            "elements": [
                "modularmachinery:blockcasing@4"
            ]
        },
        {
            "x": 3,
            "y": 0,
            "z": 4,

            "elements": [
                "modularmachinery:blockfluidinputhatch"
            ]
        },
        {
            "x": 1,
            "y": 2,
            "z": 6,
            "elements": [
                "appliedenergistics2:quartz_glass@0"
            ]
        },
        {
            "x": 2,
            "y": 2,
            "z": 0,
            "elements": [
                "appliedenergistics2:quartz_glass@0"
            ]
        },
        {
            "x": -3,
            "y": 0,
            "z": 4,
            "elements": [
                "appliedenergistics2:quartz_glass@0"
            ]
        },
        {
            "x": -1,
            "y": 4,
            "z": 5,
            "elements": [
                "appliedenergistics2:quartz_glass@0"
            ]
        },
        {
            "x": 1,
            "y": 2,
            "z": 1,
            "elements": [
                "extrautils2:pipe_3@15"
            ]
        },
        {
            "x": 2,
            "y": 4,
            "z": 3,
            "elements": [
                "appliedenergistics2:quartz_glass@0"
            ]
        },
        {
            "x": 3,
            "y": 1,
            "z": 4,
            "elements": [
                "appliedenergistics2:quartz_glass@0"
            ]
        },
        {
            "x": -2,
            "y": 4,
            "z": 1,
            "elements": [
                "appliedenergistics2:quartz_glass@0"
            ]
        },
        {
            "x": 3,
            "y": 2,
            "z": 3,
            "elements": [
                "appliedenergistics2:quartz_glass@0"
            ]
        },
        {
            "x": -3,
            "y": 4,
            "z": 2,

            "elements": [
                "modularmachinery:blockcasing@4"
            ]
        },
        {
            "x": 3,
            "y": 2,
            "z": 4,
            "elements": [
                "appliedenergistics2:quartz_glass@0"
            ]
        },
        {
            "x": -1,
            "y": -1,
            "z": 2,
            "elements": [
                "chisel:cobblestone2@8"
            ]
        },
        {
            "x": 2,
            "y": 1,
            "z": 0,
            "elements": [
                "appliedenergistics2:quartz_glass@0"
            ]
        },
        {
            "x": -3,
            "y": -1,
            "z": 0,

            "elements": [
                "modularmachinery:blockcasing@4"
            ]
        },
        {
            "x": 1,
            "y": 3,
            "z": 6,
            "elements": [
                "appliedenergistics2:quartz_glass@0"
            ]
        },
        {
            "x": 0,
            "y": 0,
            "z": 4,
            "elements": [
                "extrautils2:pipe_3@15"
            ]
        },
        {
            "x": -1,
            "y": 0,
            "z": 2,
            "elements": [
                "minecraft:obsidian@0"
            ]
        },
        {
            "x": -2,
            "y": 0,
            "z": 0,
            "elements": [
                "appliedenergistics2:quartz_glass@0"
            ]
        },
        {
            "x": 3,
            "y": 4,
            "z": 3,

            "elements": [
                "modularmachinery:blockcasing@4"
            ]
        },
        {
            "x": -2,
            "y": -1,
            "z": 2,
            "elements": [
                "chisel:cobblestone2@8"
            ]
        },
        {
            "x": -2,
            "y": 4,
            "z": 2,
            "elements": [
                "appliedenergistics2:quartz_glass@0"
            ]
        },
        {
            "x": 1,
            "y": 4,
            "z": 1,
            "elements": [
                "appliedenergistics2:quartz_glass@0"
            ]
        },
        {
            "x": 3,
            "y": 3,
            "z": 3,
            "elements": [
                "appliedenergistics2:quartz_glass@0"
            ]
        },
        {
            "x": 2,
            "y": 4,
            "z": 6,

            "elements": [
                "modularmachinery:blockcasing@4"
            ]
        },
        {
            "x": 3,
            "y": -1,
            "z": 1,
            "elements": [
                "chisel:cobblestone2@8"
            ]
        },
        {
            "x": 3,
            "y": 2,
            "z": 6,

            "elements": [
                "modularmachinery:blockcasing@4"
            ]
        },
        {
            "x": 1,
            "y": -1,
            "z": 2,
            "elements": [
                "chisel:cobblestone2@8"
            ]
        },
        {
            "x": -2,
            "y": -1,
            "z": 5,
            "elements": [
                "chisel:cobblestone2@8"
            ]
        },
        {
            "x": 3,
            "y": 3,
            "z": 6,

            "elements": [
                "modularmachinery:blockcasing@4"
            ]
        },
        {
            "x": 0,
            "y": 4,
            "z": 4,
            "elements": [
                "appliedenergistics2:quartz_glass@0"
            ]
        },
        {
            "x": 3,
            "y": 4,
            "z": 6,

            "elements": [
                "modularmachinery:blockcasing@4"
            ]
        },
        {
            "x": 1,
            "y": 0,
            "z": 2,
            "elements": [
                "minecraft:obsidian@0"
            ]
        },
        {
            "x": -3,
            "y": 4,
            "z": 6,

            "elements": [
                "modularmachinery:blockcasing@4"
            ]
        },
        {
            "x": 1,
            "y": 1,
            "z": 3,
            "elements": [
                "minecraft:obsidian@0"
            ]
        },
        {
            "x": -3,
            "y": 0,
            "z": 1,

            "elements": [
                "modularmachinery:blockfluidoutputhatch"
            ]
        },
        {
            "x": 3,
            "y": -1,
            "z": 3,
            "elements": [
                "chisel:cobblestone2@8"
            ]
        },
        {
            "x": 1,
            "y": 4,
            "z": 3,
            "elements": [
                "appliedenergistics2:quartz_glass@0"
            ]
        },
        {
            "x": 0,
            "y": 2,
            "z": 1,
            "elements": [
                "extrautils2:pipe_3@15"
            ]
        },
        {
            "x": 3,
            "y": 0,
            "z": 6,

            "elements": [
                "modularmachinery:blockcasing@4"
            ]
        },
        {
            "x": 3,
            "y": 1,
            "z": 6,

            "elements": [
                "modularmachinery:blockcasing@4"
            ]
        },
        {
            "x": -3,
            "y": -1,
            "z": 1,
            "elements": [
                "chisel:cobblestone2@8"
            ]
        },
        {
            "x": -1,
            "y": 4,
            "z": 1,
            "elements": [
                "appliedenergistics2:quartz_glass@0"
            ]
        },
        {
            "x": -1,
            "y": -1,
            "z": 6,
            "elements": [
                "chisel:cobblestone2@8"
            ]
        },
        {
            "x": -1,
            "y": 0,
            "z": 4,
            "elements": [
                "minecraft:obsidian@0"
            ]
        },
        {
            "x": -3,
            "y": 1,
            "z": 1,
            "elements": [
                "appliedenergistics2:quartz_glass@0"
            ]
        },
        {
            "x": 2,
            "y": 0,
            "z": 2,
            "elements": [
                "extrautils2:pipe_3@15"
            ]
        },
        {
            "x": 3,
            "y": 4,
            "z": 5,

            "elements": [
                "modularmachinery:blockcasing@4"
            ]
        },
        {
            "x": 0,
            "y": -1,
            "z": 3,
            "elements": [
                "minecraft:obsidian@0"
            ]
        },
        {
            "x": 0,
            "y": 0,
            "z": 6,

            "elements": [
                "modularmachinery:blockinputbus"
            ]
        },
        {
            "x": -3,
            "y": 2,
            "z": 6,

            "elements": [
                "modularmachinery:blockcasing@4"
            ]
        },
        {
            "x": 3,
            "y": -1,
            "z": 2,
            "elements": [
                "chisel:cobblestone2@8"
            ]
        },
        {
            "x": -3,
            "y": 2,
            "z": 1,
            "elements": [
                "appliedenergistics2:quartz_glass@0"
            ]
        },
        {
            "x": -2,
            "y": 4,
            "z": 3,
            "elements": [
                "appliedenergistics2:quartz_glass@0"
            ]
        },
        {
            "x": -3,
            "y": 3,
            "z": 6,

            "elements": [
                "modularmachinery:blockcasing@4"
            ]
        },
        {
            "x": -2,
            "y": 4,
            "z": 4,
            "elements": [
                "appliedenergistics2:quartz_glass@0"
            ]
        },
        {
            "x": 1,
            "y": 0,
            "z": 3,
            "elements": [
                "extrautils2:pipe_3@15"
            ]
        },
        {
            "x": -3,
            "y": 3,
            "z": 1,
            "elements": [
                "appliedenergistics2:quartz_glass@0"
            ]
        },
        {
            "x": 3,
            "y": 3,
            "z": 5,
            "elements": [
                "appliedenergistics2:quartz_glass@0"
            ]
        },
        {
            "x": 2,
            "y": -1,
            "z": 6,
            "elements": [
                "chisel:cobblestone2@8"
            ]
        },
        {
            "x": 0,
            "y": 1,
            "z": 6,
            "elements": [
                "appliedenergistics2:quartz_glass@0"
            ]
        },
        {
            "x": 2,
            "y": -1,
            "z": 1,
            "elements": [
                "chisel:cobblestone2@8"
            ]
        },
        {
            "x": 0,
            "y": 2,
            "z": 6,
            "elements": [
                "appliedenergistics2:quartz_glass@0"
            ]
        },
        {
            "x": 3,
            "y": 1,
            "z": 5,
            "elements": [
                "appliedenergistics2:quartz_glass@0"
            ]
        },
        {
            "x": 2,
            "y": 4,
            "z": 5,
            "elements": [
                "appliedenergistics2:quartz_glass@0"
            ]
        },
        {
            "x": 3,
            "y": 2,
            "z": 5,
            "elements": [
                "appliedenergistics2:quartz_glass@0"
            ]
        },
        {
            "x": 3,
            "y": 0,
            "z": 5,
            "elements": [
                "appliedenergistics2:quartz_glass@0"
            ]
        },
        {
            "x": 0,
            "y": 3,
            "z": 6,
            "elements": [
                "appliedenergistics2:quartz_glass@0"
            ]
        },
        {
            "x": -3,
            "y": 4,
            "z": 1,

            "elements": [
                "modularmachinery:blockcasing@4"
            ]
        },
        {
            "x": -1,
            "y": -1,
            "z": 1,
            "elements": [
                "chisel:cobblestone2@8"
            ]
        },
        {
            "x": 2,
            "y": 4,
            "z": 2,
            "elements": [
                "appliedenergistics2:quartz_glass@0"
            ]
        },
        {
            "x": -3,
            "y": -1,
            "z": 4,
            "elements": [
                "chisel:cobblestone2@8"
            ]
        },
        {
            "x": -2,
            "y": 0,
            "z": 1,
            "elements": [
                "extrautils2:pipe_3@15"
            ]
        },
        {
            "x": 0,
            "y": 4,
            "z": 6,

            "elements": [
                "modularmachinery:blockcasing@4"
            ]
        },
        {
            "x": -3,
            "y": 1,
            "z": 4,
            "elements": [
                "appliedenergistics2:quartz_glass@0"
            ]
        },
        {
            "x": -3,
            "y": -1,
            "z": 2,
            "elements": [
                "chisel:cobblestone2@8"
            ]
        },
        {
            "x": 0,
            "y": -1,
            "z": 1,
            "elements": [
                "chisel:cobblestone2@8"
            ]
        },
        {
            "x": -1,
            "y": 4,
            "z": 2,
            "elements": [
                "appliedenergistics2:quartz_glass@0"
            ]
        },
        {
            "x": -2,
            "y": -1,
            "z": 4,
            "elements": [
                "chisel:cobblestone2@8"
            ]
        },
        {
            "x": -2,
            "y": 0,
            "z": 4,
            "elements": [
                "extrautils2:pipe_3@15"
            ]
        },
        {
            "x": 2,
            "y": -1,
            "z": 5,
            "elements": [
                "chisel:cobblestone2@8"
            ]
        },
        {
            "x": -3,
            "y": 2,
            "z": 4,
            "elements": [
                "appliedenergistics2:quartz_glass@0"
            ]
        },
        {
            "x": -3,
            "y": 1,
            "z": 3,
            "elements": [
                "appliedenergistics2:quartz_glass@0"
            ]
        },
        {
            "x": 3,
            "y": 2,
            "z": 0,

            "elements": [
                "modularmachinery:blockcasing@4"
            ]
        },
        {
            "x": -1,
            "y": -1,
            "z": 3,
            "elements": [
                "minecraft:obsidian@0"
            ]
        },
        {
            "x": -1,
            "y": 0,
            "z": 6,
            "elements": [
                "appliedenergistics2:quartz_glass@0"
            ]
        },
        {
            "x": -3,
            "y": 4,
            "z": 3,

            "elements": [
                "modularmachinery:blockcasing@4"
            ]
        },
        {
            "x": -2,
            "y": 3,
            "z": 6,
            "elements": [
                "appliedenergistics2:quartz_glass@0"
            ]
        },
        {
            "x": -2,
            "y": 2,
            "z": 6,
            "elements": [
                "appliedenergistics2:quartz_glass@0"
            ]
        },
        {
            "x": 1,
            "y": -1,
            "z": 1,
            "elements": [
                "chisel:cobblestone2@8"
            ]
        },
        {
            "x": -3,
            "y": 2,
            "z": 3,
            "elements": [
                "appliedenergistics2:quartz_glass@0"
            ]
        },
        {
            "x": 3,
            "y": 4,
            "z": 1,

            "elements": [
                "modularmachinery:blockcasing@4"
            ]
        },
        {
            "x": 3,
            "y": 1,
            "z": 0,

            "elements": [
                "modularmachinery:blockcasing@4"
            ]
        },
        {
            "x": 0,
            "y": 0,
            "z": 3,
            "elements": [
                "extrautils2:pipe_3@15"
            ]
        },
        {
            "x": -1,
            "y": 1,
            "z": 6,
            "elements": [
                "appliedenergistics2:quartz_glass@0"
            ]
        },
        {
            "x": -3,
            "y": 0,
            "z": 0,

            "elements": [
                "modularmachinery:blockcasing@4"
            ]
        },
        {
            "x": 0,
            "y": 1,
            "z": 3,
            "elements": [
                "extrautils2:pipe_3@15"
            ]
        },
        {
            "x": -2,
            "y": 4,
            "z": 6,

            "elements": [
                "modularmachinery:blockcasing@4"
            ]
        },
        {
            "x": -2,
            "y": -1,
            "z": 6,
            "elements": [
                "chisel:cobblestone2@8"
            ]
        },
        {
            "x": 3,
            "y": 4,
            "z": 0,

            "elements": [
                "modularmachinery:blockcasing@4"
            ]
        },
        {
            "x": -2,
            "y": -1,
            "z": 1,
            "elements": [
                "chisel:cobblestone2@8"
            ]
        },
        {
            "x": 0,
            "y": 2,
            "z": 3,
            "elements": [
                "extrautils2:pipe_3@15"
            ]
        },
        {
            "x": 2,
            "y": 4,
            "z": 4,
            "elements": [
                "appliedenergistics2:quartz_glass@0"
            ]
        },
        {
            "x": -3,
            "y": 0,
            "z": 3,

            "elements": [
                "modularmachinery:blockoutputbus"
            ]
        },
        {
            "x": 0,
            "y": -1,
            "z": 5,
            "elements": [
                "chisel:cobblestone2@8"
            ]
        },
        {
            "x": 3,
            "y": 3,
            "z": 0,

            "elements": [
                "modularmachinery:blockcasing@4"
            ]
        },
        {
            "x": -3,
            "y": 2,
            "z": 0,

            "elements": [
                "modularmachinery:blockcasing@4"
            ]
        },
        {
            "x": -3,
            "y": -1,
            "z": 3,
            "elements": [
                "chisel:cobblestone2@8"
            ]
        },
        {
            "x": -1,
            "y": 1,
            "z": 3,
            "elements": [
                "minecraft:obsidian@0"
            ]
        },
        {
            "x": -3,
            "y": -1,
            "z": 6,

            "elements": [
                "modularmachinery:blockcasing@4"
            ]
        },
        {
            "x": 0,
            "y": -1,
            "z": 4,
            "elements": [
                "minecraft:obsidian@0"
            ]
        },
        {
            "x": -3,
            "y": 0,
            "z": 6,

            "elements": [
                "modularmachinery:blockcasing@4"
            ]
        },
        {
            "x": -2,
            "y": 4,
            "z": 5,
            "elements": [
                "appliedenergistics2:quartz_glass@0"
            ]
        },
        {
            "x": 0,
            "y": 4,
            "z": 0,

            "elements": [
                "modularmachinery:blockcasing@4"
            ]
        },
        {
            "x": 3,
            "y": 0,
            "z": 1,
            "elements": [
                "appliedenergistics2:quartz_glass@0"
            ]
        },
        {
            "x": -3,
            "y": 1,
            "z": 6,

            "elements": [
                "modularmachinery:blockcasing@4"
            ]
        },
        {
            "x": 2,
            "y": 2,
            "z": 1,
            "elements": [
                "extrautils2:pipe_3@15"
            ]
        },
        {
            "x": -1,
            "y": 4,
            "z": 4,
            "elements": [
                "appliedenergistics2:quartz_glass@0"
            ]
        },
        {
            "x": 3,
            "y": 1,
            "z": 1,
            "elements": [
                "appliedenergistics2:quartz_glass@0"
            ]
        },
        {
            "x": 0,
            "y": 3,
            "z": 0,
            "elements": [
                "appliedenergistics2:quartz_glass@0"
            ]
        },
        {
            "x": 3,
            "y": -1,
            "z": 5,
            "elements": [
                "chisel:cobblestone2@8"
            ]
        },
        {
            "x": -2,
            "y": 0,
            "z": 3,
            "elements": [
                "extrautils2:pipe_3@15"
            ]
        },
        {
            "x": 1,
            "y": 0,
            "z": 4,
            "elements": [
                "minecraft:obsidian@0"
            ]
        },
        {
            "x": 3,
            "y": 0,
            "z": 0,

            "elements": [
                "modularmachinery:blockcasing@4"
            ]
        },
        {
            "x": -3,
            "y": 3,
            "z": 3,
            "elements": [
                "appliedenergistics2:quartz_glass@0"
            ]
        },
        {
            "x": -3,
            "y": 4,
            "z": 0,

            "elements": [
                "modularmachinery:blockcasing@4"
            ]
        },
        {
            "x": 0,
            "y": 2,
            "z": 0,
            "elements": [
                "appliedenergistics2:quartz_glass@0"
            ]
        },
        {
            "x": 3,
            "y": 3,
            "z": 1,
            "elements": [
                "appliedenergistics2:quartz_glass@0"
            ]
        },
        {
            "x": -2,
            "y": -1,
            "z": 3,
            "elements": [
                "chisel:cobblestone2@8"
            ]
        },
        {
            "x": 1,
            "y": -1,
            "z": 4,
            "elements": [
                "chisel:cobblestone2@8"
            ]
        },
        {
            "x": -2,
            "y": 0,
            "z": 6,
            "elements": [
                "appliedenergistics2:quartz_glass@0"
            ]
        },
        {
            "x": 1,
            "y": 4,
            "z": 5,
            "elements": [
                "appliedenergistics2:quartz_glass@0"
            ]
        },
        {
            "x": 2,
            "y": 0,
            "z": 1,
            "elements": [
                "extrautils2:pipe_3@15"
            ]
        },
        {
            "x": -3,
            "y": 1,
            "z": 0,

            "elements": [
                "modularmachinery:blockcasing@4"
            ]
        },
        {
            "x": 2,
            "y": -1,
            "z": 0,
            "elements": [
                "chisel:cobblestone2@8"
            ]
        },
        {
            "x": -3,
            "y": 3,
            "z": 0,

            "elements": [
                "modularmachinery:blockcasing@4"
            ]
        },
        {
            "x": 0,
            "y": 1,
            "z": 0,
            "elements": [
                "appliedenergistics2:quartz_glass@0"
            ]
        },
        {
            "x": -1,
            "y": -1,
            "z": 0,
            "elements": [
                "chisel:cobblestone2@8"
            ]
        },
        {
            "x": 3,
            "y": 2,
            "z": 1,
            "elements": [
                "appliedenergistics2:quartz_glass@0"
            ]
        },
        {
            "x": -1,
            "y": 0,
            "z": 3,
            "elements": [
                "extrautils2:pipe_3@15"
            ]
        },
        {
            "x": 3,
            "y": 4,
            "z": 2,

            "elements": [
                "modularmachinery:blockcasing@4"
            ]
        },
        {
            "x": 0,
            "y": 4,
            "z": 1,
            "elements": [
                "appliedenergistics2:quartz_glass@0"
            ]
        },
        {
            "x": 2,
            "y": 1,
            "z": 1,
            "elements": [
                "extrautils2:pipe_3@15"
            ]
        },
        {
            "x": 2,
            "y": 0,
            "z": 4,
            "elements": [
                "extrautils2:pipe_3@15"
            ]
        },
        {
            "x": -2,
            "y": 1,
            "z": 6,
            "elements": [
                "appliedenergistics2:quartz_glass@0"
            ]
        }
    ]}